Workbook
Name CleanedData: Cleaned!$A$2:$T$29
Name Region: Cleaned!$J:$J
Name Revenue: Cleaned!$R:$R
Name Slicer_Category: #N/A
Name Slicer_Region: #N/A
Name Slicer_Status: #N/A
Name Status: Cleaned!$R:$R

Sheet Raw Data
A1: Order ID | B1: Customer ID | C1: Customer Name | D1: Product ID | E1: Product Name | F1: Category | G1: Region | H1: Order Date | I1: Delivery Date | J1: Quantity | K1: Unit Price | L1: Discount % | M1: Status
A2: ORD001 | B2: C001 | C2: priya sharma | D2: P003 | E2: Laptop Pro | F2: Electronics | G2: north | H2: 46143 | I2: 46296 | J2: 2 | K2: ₹55000 | L2: 0.1 | M2: delivered
A3: ORD002 | B3: C002 | C3: ARJUN NAIR | D3: P001 | E3: Cotton Tshirt | F3: Fashion | G3: south | H3: 46357 | I3: 18-01-2026 | J3: 3 | K3: ₹799 | L3: 0.05 | M3: Pending
A4: ORD003 | B4: C003 | C4: sneha reddy | D4: P002 | E4: Face Cream | F4: Beauty | G4: EAST | H4: 46083 | I4: 46236 | J4: 1 | K4: ₹1200 | L4: 0 | M4: Delivered
A5: ORD004 | B5: C001 | C5: priya sharma | D5: P004 | E5: Running Shoes | F5: Sports | G5: North | H5: 18-02-2026 | I5: 25-02-2026 | J5: 1 | K5: ₹3500 | L5: 0.15 | M5: delivered
A6: ORD005 | B6: C004 | C6: RAHUL DAS | D6: P001 | E6: Cotton Tshirt | F6: Fashion | G6: south | H6: 25-02-2026 | I6: 46084 | J6: 5 | K6: ₹799 | L6: 0.05 | M6: Cancelled
A7: ORD006 | B7: C005 | C7: divya krishna | D7: P005 | E7: Rice Cooker | F7: Kitchen | G7: East | H7: 46206 | I7: 14-03-2026 | J7: 1 | K7: ₹2800 | L7: 0.1 | M7: DELIVERED
A8: ORD007 | B8: C002 | C8: ARJUN NAIR | D8: P003 | E8: Laptop Pro | F8: Electronics | G8: South | H8: 14-03-2026 | I8: 20-03-2026 | J8: 1 | K8: ₹55000 | L8: 0.08 | M8: Pending
A9: ORD008 | B9: C006 | C9: meera nair | D9: P002 | E9: Face Cream | F9: Beauty | G9: NORTH | H9: 22-03-2026 | I9: 28-03-2026 | J9: 2 | K9: ₹1200 | L9: 0 | M9: delivered
A10: ORD009 | B10: C003 | C10: sneha reddy | D10: P004 | E10: Running Shoes | F10: Sports | G10: East | H10: 46026 | I10: 46207 | J10: 3 | K10: ₹3500 | L10: 0.1 | M10: DELIVERED
A11: ORD010 | B11: C007 | C11: KIRAN RAO | D11: P005 | E11: Rice Cooker | F11: Kitchen | G11: west | H11: 46238 | I11: 15-04-2026 | J11: 2 | K11: ₹2800 | L11: 0.05 | M11: delivered
A12: ORD011 | B12: C008 | C12: pooja singh | D12: P001 | E12: Cotton Tshirt | F12: Fashion | G12: North | H12: 15-04-2026 | I12: 21-04-2026 | J12: 4 | K12: ₹799 | L12: 0 | M12: Delivered
A13: ORD012 | B13: C004 | C13: RAHUL DAS | D13: P003 | E13: Laptop Pro | F13: Electronics | G13: SOUTH | H13: 20-04-2026 | I13: 27-04-2026 | J13: 1 | K13: ₹55000 | L13: 0.12 | M13: delivered
A14: ORD013 | B14: C009 | C14: arun kumar | D14: P002 | E14: Face Cream | F14: Beauty | G14: East | H14: 28-04-2026 | I14: 46117 | J14: 3 | K14: ₹1200 | L14: 0.05 | M14: Pending
A15: ORD014 | B15: C005 | C15: divya krishna | D15: P005 | E15: Rice Cooker | F15: Kitchen | G15: WEST | H15: 46147 | I15: 12-05-202 | J15: 1 | K15: ₹2800 | L15: 0 | M15: DELIVERED
A16: ORD015 | B16: C010 | C16: VIJAY KUMAR | D16: P004 | E16: Running Shoes | F16: Sports | G16: north | H16: 46361 | I16: 19-05-2026 | J16: 2 | K16: ₹3500 | L16: 0.08 | M16: delivered
A17: ORD016 | B17: C001 | C17: priya sharma | D17: P001 | E17: Cotton Tshirt | F17: Fashion | G17: North | H17: 18-05-2026 | I17: 24-05-2026 | J17: 6 | K17: ₹799 | L17: 0.1 | M17: Delivered
A18: ORD017 | B18: C006 | C18: meera nair | D18: P003 | E18: Laptop Pro | F18: Electronics | G18: EAST | H18: 25-05-2026 | I18: 31-05-2026 | J18: 1 | K18: ₹55000 | L18: 0.05 | M18: DELIVERED
A19: ORD018 | B19: C002 | C19: ARJUN NAIR | D19: P002 | E19: Face Cream | F19: Beauty | G19: South | H19: 46028 | I19: 46209 | J19: 2 | K19: ₹1200 | L19: 0 | M19: Pending
A20: ORD019 | B20: C007 | C20: KIRAN RAO | D20: P004 | E20: Running Shoes | F20: Sports | G20: West | H20: 46148 | I20: 46362 | J20: 3 | K20: ₹3500 | L20: 0.15 | M20: delivered
A21: ORD020 | B21: C008 | C21: pooja singh | D21: P005 | E21: Rice Cooker | F21: Kitchen | G21: NORTH | H21: 46301 | I21: 17-06-2026 | J21: 1 | K21: ₹2800 | L21: 0.1 | M21: Delivered
A22: ORD021 | B22: C009 | C22: arun kumar | D22: P001 | E22: Cotton Tshirt | F22: Fashion | G22: EAST | H22: 46362 | I22: 18-06-2026 | J22: 2 | K22: ₹799 | L22: 0.05 | M22: DELIVERED
A23: ORD022 | B23: C010 | C23: VIJAY KUMAR | D23: P003 | E23: Laptop Pro | F23: Electronics | G23: South | H23: 14-06-2026 | I23: 21-06-2026 | J23: 1 | K23: ₹55000 | L23: 0 | M23: Pending
A24: ORD023 | B24: C003 | C24: sneha reddy | D24: P002 | E24: Face Cream | F24: Beauty | G24: north | H24: 46028 | I24: 22-06-2026 | J24: 4 | K24: ₹1200 | L24: 0.1 | M24: delivered
A25: ORD024 | B25: C004 | C25: RAHUL DAS | D25: P004 | E25: Running Shoes | F25: Sports | G25: WEST | H25: 18-06-2026 | I25: 25-06-2026 | J25: 2 | K25: ₹3500 | L25: 0.05 | M25: Delivered
A26: ORD025 | B26: C005 | C26: divya krishna | D26: P005 | E26: Rice Cooker | F26: Kitchen | G26: North | H26: 20-06-2026 | I26: 27-06-2026 | J26: 3 | K26: ₹2800 | L26: 0.08 | M26: DELIVERED
A27: ORD003 | B27: C003 | C27: sneha reddy | D27: P002 | E27: Face Cream | F27: Beauty | G27: EAST | H27: 46083 | I27: 46236 | J27: 1 | K27: ₹1200 | L27: 0 | M27: Delivered
A28: ORD026 | B28: C006 | C28: meera nair | D28: P001 | E28: Cotton Tshirt | F28: Fashion | G28: nrth | H28: 21-06-2026 | I28: 28-06-2026 | J28: 3 | K28: ₹799 | L28: 0.05 | M28: delivered
A29: ORD027 | B29: C007 | C29: KIRAN RAO | D29: P003 | E29: Laptop Pro | F29: Electronics | G29: West | H29: 22-06-2026 | I29: 29-06-2026 | J29: 1 | L29: 0.1 | M29: Pending
A30: ORD028 | B30: C008 | C30: pooja singh | D30: P004 | E30: Running Shoes | F30: Sports | G30: South | H30: 23-06-2026 | I30: 30-06-2026 | J30: 2 | K30: ₹3500 | L30: 0
A31: ORD029 | B31: C009 | C31: arun kumar | D31: P005 | E31: Rice Cooker | F31: Kitchen | G31: East | H31: 24-06-2026 | I31: 46029 | J31: 2 | K31: ₹2800 | L31: 0.05 | M31: delivered

Sheet ProductDB
A1: Product ID | B1: Product Name | C1: Category | D1: Unit Price (₹) | E1: Cost Price (₹) | F1: Profit Margin %
A2: P001 | B2: Cotton Tshirt | C2: Fashion | D2: 799 | E2: 350 | F2: 0.56
A3: P002 | B3: Face Cream | C3: Beauty | D3: 1200 | E3: 480 | F3: 0.6
A4: P003 | B4: Laptop Pro | C4: Electronics | D4: 55000 | E4: 38000 | F4: 0.31
A5: P004 | B5: Running shoes | C5: Sports | D5: 3500 | E5: 1500 | F5: 0.57
A6: P005 | B6: Rice Cooker | C6: Kitchen | D6: 2800 | E6: 1100 | F6: 0.61

Sheet CustomerDB
A1: Customer ID | B1: Customer Name | C1: City | D1: State | E1: Customer Since | F1: Customer Type
A2: C001 | B2: Proya Sharma | C2: Bangalore | D2: Karnataka | E2: 15-03-2023 | F2: Premium
A3: C002 | B3: Arjun Nair | C3: Chennai | D3: Tamil Nadu | E3: 22-07-2022 | F3: Regular
A4: C003 | B4: Sneha Reddy | C4: Hyderabad | D4: Telangana | E4: 45566 | F4: Regular
A5: C004 | B5: Rahul Das | C5: Kolkata | D5: West Bengal | E5: 44325 | F5: Premium
A6: C005 | B6: Divya Krishna | C6: Mumbai | D6: Maharashtra | E6: 18-11-2023 | F6: Regular
A7: C006 | B7: Meera Nair | C7: Kochi | D7: Kerala | E7: 30-04-2022 | F7: Premium
A8: C007 | B8: Kiran Rao | C8: Pune | D8: Maharashtra | E8: 14-06-2023 | F8: Regular
A9: C008 | B9: Pooja Singh | C9: Delhi | D9: Delhi | E9: 45324 | F9: Regular
A10: C009 | B10: Arun Kumar | C10: Ahmedabad | D10: Gujarat | E10: 25-08-2022 | F10: Premium
A11: C010 | B11: Vijay Kumar | C11: Jaipur | D11: Rajasthan | E11: 44512 | F11: Regular

Sheet Cleaned
A1: Order ID | B1: Customer ID | C1: Customer Name | D1: City | E1: State | F1: Customer Type | G1: Product ID | H1: Product Name | I1: Category | J1: Region | K1: Order Date | L1: Delivery Date | M1: Delivery Days | N1: Quantity | O1: Unit Price | P1: Discount % | Q1: Revenue | R1: Status | S1: Data Flag | T1: Month
A2: ORD001 | B2: C001 | C2: Priya Sharma | D2: Bangalore | E2: Karnataka | F2: Premium | G2: P003 | H2: Laptop Pro | I2: Electronics | J2: North | K2: 46027 | L2: 46032 | M2: 5 | N2: 2 | O2: 55000 | P2: 10 | Q2: 99000 | R2: Delivered | S2: OK | T2: Jan-2026
A3: =TRIM(UPPER('Raw Data'!A3)) -> ORD002 | B3: =TRIM(UPPER('Raw Data'!B3)) -> C002 | C3: =TRIM(PROPER('Raw Data'!C3)) -> Arjun Nair | D3: =IFERROR(VLOOKUP(B3,CustomerDB!A2:F12,3,0),"unknown") -> Chennai | E3: =IFERROR(VLOOKUP(B3,CustomerDB!A2:F12,4,0),"Unknown") -> Tamil Nadu | F3: =IFERROR(VLOOKUP(B3,CustomerDB!A2:F12,6,0),"Unknown") -> Regular | G3: =TRIM(UPPER('Raw Data'!D3)) -> P001 | H3: =IFERROR(VLOOKUP(G3,ProductDB!A2:F7,2,0),"Unknown") -> Cotton Tshirt | I3: =IFERROR(VLOOKUP(G3,ProductDB!A2:F7,3,0),"Unknown") -> Fashion | J3: =IF(TRIM(PROPER('Raw Data'!G3))="Nrth","North",TRIM(PROPER('Raw Data'!G3))) -> South | K3: =IFERROR(DATEVALUE(TEXT('Raw Data'!H3,"DD-MM-YYYY")),"Invalid Date") -> 46034 | L3: 18-01-2026 | M3: 6 | N3: =IFERROR(VALUE('Raw Data'!J3),"Check") -> 3 | O3: =IFERROR(VALUE(SUBSTITUTE('Raw Data'!K3,"₹","")),0) -> 799 | P3: =IFERROR('Raw Data'!L3*100,0) -> 5 | Q3: =IFERROR(N3*O3*(1-P3/100),0) -> 2277.15 | R3: =IF(TRIM('Raw Data'!M3)="","Unknown",TRIM(PROPER('Raw Data'!M3))) -> Pending | S3: =IF(O3=0,"Missing Price",IF(N3="Check","Wrong Quantity",IF(R3="Unknown","Missing Status",IF(J3="Unknown","Check Region","OK")))) -> OK | T3: =TEXT(K3,"MMM-YYYY") -> Jan-2026
A4: =TRIM(UPPER('Raw Data'!A4)) -> ORD003 | B4: =TRIM(UPPER('Raw Data'!B4)) -> C003 | C4: =TRIM(PROPER('Raw Data'!C4)) -> Sneha Reddy | D4: =IFERROR(VLOOKUP(B4,CustomerDB!A3:F13,3,0),"unknown") -> Hyderabad | E4: =IFERROR(VLOOKUP(B4,CustomerDB!A3:F13,4,0),"Unknown") -> Telangana | F4: =IFERROR(VLOOKUP(B4,CustomerDB!A3:F13,6,0),"Unknown") -> Regular | G4: =TRIM(UPPER('Raw Data'!D4)) -> P002 | H4: =IFERROR(VLOOKUP(G4,ProductDB!A3:F8,2,0),"Unknown") -> Face Cream | I4: =IFERROR(VLOOKUP(G4,ProductDB!A3:F8,3,0),"Unknown") -> Beauty | J4: =IF(TRIM(PROPER('Raw Data'!G4))="Nrth","North",TRIM(PROPER('Raw Data'!G4))) -> East | K4: =IFERROR(DATEVALUE(TEXT('Raw Data'!H4,"DD-MM-YYYY")),"Invalid Date") -> 46056 | L4: =IFERROR(DATEVALUE(TEXT('Raw Data'!I4,"DD-MM-YYYY")),"Invalid Date") -> 46061 | M4: =IFERROR(L4-K4,"N/A") -> 5 | N4: =IFERROR(VALUE('Raw Data'!J4),"Check") -> 1 | O4: =IFERROR(VALUE(SUBSTITUTE('Raw Data'!K4,"₹","")),0) -> 1200 | P4: =IFERROR('Raw Data'!L4*100,0) -> 0 | Q4: =IFERROR(N4*O4*(1-P4/100),0) -> 1200 | R4: =IF(TRIM('Raw Data'!M4)="","Unknown",TRIM(PROPER('Raw Data'!M4))) -> Delivered | S4: =IF(O4=0,"Missing Price",IF(N4="Check","Wrong Quantity",IF(R4="Unknown","Missing Status",IF(J4="Unknown","Check Region","OK")))) -> OK | T4: =TEXT(K4,"MMM-YYYY") -> Feb-2026
A5: =TRIM(UPPER('Raw Data'!A5)) -> ORD004 | B5: =TRIM(UPPER('Raw Data'!B5)) -> C001 | C5: =TRIM(PROPER('Raw Data'!C5)) -> Priya Sharma | D5: Bangalore | E5: Karnataka | F5: Premium | G5: =TRIM(UPPER('Raw Data'!D5)) -> P004 | H5: =IFERROR(VLOOKUP(G5,ProductDB!A4:F9,2,0),"Unknown") -> Running shoes | I5: =IFERROR(VLOOKUP(G5,ProductDB!A4:F9,3,0),"Unknown") -> Sports | J5: =IF(TRIM(PROPER('Raw Data'!G5))="Nrth","North",TRIM(PROPER('Raw Data'!G5))) -> North | K5: 18-02-2026 | L5: 25-02-2026 | M5: 7 | N5: =IFERROR(VALUE('Raw Data'!J5),"Check") -> 1 | O5: =IFERROR(VALUE(SUBSTITUTE('Raw Data'!K5,"₹","")),0) -> 3500 | P5: =IFERROR('Raw Data'!L5*100,0) -> 15 | Q5: =IFERROR(N5*O5*(1-P5/100),0) -> 2975 | R5: =IF(TRIM('Raw Data'!M5)="","Unknown",TRIM(PROPER('Raw Data'!M5))) -> Delivered | S5: =IF(O5=0,"Missing Price",IF(N5="Check","Wrong Quantity",IF(R5="Unknown","Missing Status",IF(J5="Unknown","Check Region","OK")))) -> OK | T5: 46054
A6: =TRIM(UPPER('Raw Data'!A6)) -> ORD005 | B6: =TRIM(UPPER('Raw Data'!B6)) -> C004 | C6: =TRIM(PROPER('Raw Data'!C6)) -> Rahul Das | D6: =IFERROR(VLOOKUP(B6,CustomerDB!A5:F15,3,0),"unknown") -> Kolkata | E6: =IFERROR(VLOOKUP(B6,CustomerDB!A5:F15,4,0),"Unknown") -> West Bengal | F6: =IFERROR(VLOOKUP(B6,CustomerDB!A5:F15,6,0),"Unknown") -> Premium | G6: =TRIM(UPPER('Raw Data'!D6)) -> P001 | H6: Cotton Tshirt | I6: Fashion | J6: =IF(TRIM(PROPER('Raw Data'!G6))="Nrth","North",TRIM(PROPER('Raw Data'!G6))) -> South | K6: 25-02-2026 | L6: =IFERROR(DATEVALUE(TEXT('Raw Data'!I6,"DD-MM-YYYY")),"Invalid Date") -> 46084 | M6: 6 | N6: =IFERROR(VALUE('Raw Data'!J6),"Check") -> 5 | O6: =IFERROR(VALUE(SUBSTITUTE('Raw Data'!K6,"₹","")),0) -> 799 | P6: =IFERROR('Raw Data'!L6*100,0) -> 5 | Q6: =IFERROR(N6*O6*(1-P6/100),0) -> 3795.25 | R6: =IF(TRIM('Raw Data'!M6)="","Unknown",TRIM(PROPER('Raw Data'!M6))) -> Cancelled | S6: =IF(O6=0,"Missing Price",IF(N6="Check","Wrong Quantity",IF(R6="Unknown","Missing Status",IF(J6="Unknown","Check Region","OK")))) -> OK | T6: 46054
A7: =TRIM(UPPER('Raw Data'!A7)) -> ORD006 | B7: =TRIM(UPPER('Raw Data'!B7)) -> C005 | C7: =TRIM(PROPER('Raw Data'!C7)) -> Divya Krishna | D7: =IFERROR(VLOOKUP(B7,CustomerDB!A6:F16,3,0),"unknown") -> Mumbai | E7: =IFERROR(VLOOKUP(B7,CustomerDB!A6:F16,4,0),"Unknown") -> Maharashtra | F7: =IFERROR(VLOOKUP(B7,CustomerDB!A6:F16,6,0),"Unknown") -> Regular | G7: =TRIM(UPPER('Raw Data'!D7)) -> P005 | H7: =IFERROR(VLOOKUP(G7,ProductDB!A6:F11,2,0),"Unknown") -> Rice Cooker | I7: =IFERROR(VLOOKUP(G7,ProductDB!A6:F11,3,0),"Unknown") -> Kitchen | J7: =IF(TRIM(PROPER('Raw Data'!G7))="Nrth","North",TRIM(PROPER('Raw Data'!G7))) -> East | K7: =IFERROR(DATEVALUE(TEXT('Raw Data'!H7,"DD-MM-YYYY")),"Invalid Date") -> 46088 | L7: 14-03-2026 | M7: 7 | N7: =IFERROR(VALUE('Raw Data'!J7),"Check") -> 1 | O7: =IFERROR(VALUE(SUBSTITUTE('Raw Data'!K7,"₹","")),0) -> 2800 | P7: =IFERROR('Raw Data'!L7*100,0) -> 10 | Q7: =IFERROR(N7*O7*(1-P7/100),0) -> 2520 | R7: =IF(TRIM('Raw Data'!M7)="","Unknown",TRIM(PROPER('Raw Data'!M7))) -> Delivered | S7: =IF(O7=0,"Missing Price",IF(N7="Check","Wrong Quantity",IF(R7="Unknown","Missing Status",IF(J7="Unknown","Check Region","OK")))) -> OK | T7: =TEXT(K7,"MMM-YYYY") -> Mar-2026
A8: =TRIM(UPPER('Raw Data'!A8)) -> ORD007 | B8: =TRIM(UPPER('Raw Data'!B8)) -> C002 | C8: =TRIM(PROPER('Raw Data'!C8)) -> Arjun Nair | D8: Chennai | E8: Tamil Nadu | F8: Regular | G8: =TRIM(UPPER('Raw Data'!D8)) -> P003 | H8: Laptop Pro | I8: Electronics | J8: =IF(TRIM(PROPER('Raw Data'!G8))="Nrth","North",TRIM(PROPER('Raw Data'!G8))) -> South | K8: 14-03-2026 | L8: 20-03-2026 | M8: 6 | N8: =IFERROR(VALUE('Raw Data'!J8),"Check") -> 1 | O8: =IFERROR(VALUE(SUBSTITUTE('Raw Data'!K8,"₹","")),0) -> 55000 | P8: =IFERROR('Raw Data'!L8*100,0) -> 8 | Q8: =IFERROR(N8*O8*(1-P8/100),0) -> 50600 | R8: =IF(TRIM('Raw Data'!M8)="","Unknown",TRIM(PROPER('Raw Data'!M8))) -> Pending | S8: =IF(O8=0,"Missing Price",IF(N8="Check","Wrong Quantity",IF(R8="Unknown","Missing Status",IF(J8="Unknown","Check Region","OK")))) -> OK | T8: 46082
A9: =TRIM(UPPER('Raw Data'!A9)) -> ORD008 | B9: =TRIM(UPPER('Raw Data'!B9)) -> C006 | C9: =TRIM(PROPER('Raw Data'!C9)) -> Meera Nair | D9: Kochi | E9: Kerala | F9: Premium | G9: =TRIM(UPPER('Raw Data'!D9)) -> P002 | H9: Face Cream | I9: Beauty | J9: =IF(TRIM(PROPER('Raw Data'!G9))="Nrth","North",TRIM(PROPER('Raw Data'!G9))) -> North | K9: 22-03-2026 | L9: 28-03-2026 | M9: 6 | N9: =IFERROR(VALUE('Raw Data'!J9),"Check") -> 2 | O9: =IFERROR(VALUE(SUBSTITUTE('Raw Data'!K9,"₹","")),0) -> 1200 | P9: =IFERROR('Raw Data'!L9*100,0) -> 0 | Q9: =IFERROR(N9*O9*(1-P9/100),0) -> 2400 | R9: =IF(TRIM('Raw Data'!M9)="","Unknown",TRIM(PROPER('Raw Data'!M9))) -> Delivered | S9: =IF(O9=0,"Missing Price",IF(N9="Check","Wrong Quantity",IF(R9="Unknown","Missing Status",IF(J9="Unknown","Check Region","OK")))) -> OK | T9: 46082
A10: =TRIM(UPPER('Raw Data'!A10)) -> ORD009 | B10: =TRIM(UPPER('Raw Data'!B10)) -> C003 | C10: =TRIM(PROPER('Raw Data'!C10)) -> Sneha Reddy | D10: Hyderabad | E10: Telangana | F10: Regular | G10: =TRIM(UPPER('Raw Data'!D10)) -> P004 | H10: Running Shoes | I10: Sports | J10: =IF(TRIM(PROPER('Raw Data'!G10))="Nrth","North",TRIM(PROPER('Raw Data'!G10))) -> East | K10: =IFERROR(DATEVALUE(TEXT('Raw Data'!H10,"DD-MM-YYYY")),"Invalid Date") -> 46113 | L10: =IFERROR(DATEVALUE(TEXT('Raw Data'!I10,"DD-MM-YYYY")),"Invalid Date") -> 46119 | M10: =IFERROR(L10-K10,"N/A") -> 6 | N10: =IFERROR(VALUE('Raw Data'!J10),"Check") -> 3 | O10: =IFERROR(VALUE(SUBSTITUTE('Raw Data'!K10,"₹","")),0) -> 3500 | P10: =IFERROR('Raw Data'!L10*100,0) -> 10 | Q10: =IFERROR(N10*O10*(1-P10/100),0) -> 9450 | R10: =IF(TRIM('Raw Data'!M10)="","Unknown",TRIM(PROPER('Raw Data'!M10))) -> Delivered | S10: =IF(O10=0,"Missing Price",IF(N10="Check","Wrong Quantity",IF(R10="Unknown","Missing Status",IF(J10="Unknown","Check Region","OK")))) -> OK | T10: =TEXT(K10,"MMM-YYYY") -> Apr-2026
A11: =TRIM(UPPER('Raw Data'!A11)) -> ORD010 | B11: =TRIM(UPPER('Raw Data'!B11)) -> C007 | C11: =TRIM(PROPER('Raw Data'!C11)) -> Kiran Rao | D11: Pune | E11: Maharashtra | F11: Regular | G11: =TRIM(UPPER('Raw Data'!D11)) -> P005 | H11: Rice Cooker | I11: Kitchen | J11: =IF(TRIM(PROPER('Raw Data'!G11))="Nrth","North",TRIM(PROPER('Raw Data'!G11))) -> West | K11: =IFERROR(DATEVALUE(TEXT('Raw Data'!H11,"DD-MM-YYYY")),"Invalid Date") -> 46120 | L11: 15-04-2026 | M11: 7 | N11: =IFERROR(VALUE('Raw Data'!J11),"Check") -> 2 | O11: =IFERROR(VALUE(SUBSTITUTE('Raw Data'!K11,"₹","")),0) -> 2800 | P11: =IFERROR('Raw Data'!L11*100,0) -> 5 | Q11: =IFERROR(N11*O11*(1-P11/100),0) -> 5320 | R11: =IF(TRIM('Raw Data'!M11)="","Unknown",TRIM(PROPER('Raw Data'!M11))) -> Delivered | S11: =IF(O11=0,"Missing Price",IF(N11="Check","Wrong Quantity",IF(R11="Unknown","Missing Status",IF(J11="Unknown","Check Region","OK")))) -> OK | T11: =TEXT(K11,"MMM-YYYY") -> Apr-2026
A12: =TRIM(UPPER('Raw Data'!A12)) -> ORD011 | B12: =TRIM(UPPER('Raw Data'!B12)) -> C008 | C12: =TRIM(PROPER('Raw Data'!C12)) -> Pooja Singh | D12: Delhi | E12: Delhi | F12: Regular | G12: =TRIM(UPPER('Raw Data'!D12)) -> P001 | H12: Cotton Tshirt | I12: Fashion | J12: =IF(TRIM(PROPER('Raw Data'!G12))="Nrth","North",TRIM(PROPER('Raw Data'!G12))) -> North | K12: 15-04-2026 | L12: 21-04-2026 | M12: 6 | N12: =IFERROR(VALUE('Raw Data'!J12),"Check") -> 4 | O12: =IFERROR(VALUE(SUBSTITUTE('Raw Data'!K12,"₹","")),0) -> 799 | P12: =IFERROR('Raw Data'!L12*100,0) -> 0 | Q12: =IFERROR(N12*O12*(1-P12/100),0) -> 3196 | R12: =IF(TRIM('Raw Data'!M12)="","Unknown",TRIM(PROPER('Raw Data'!M12))) -> Delivered | S12: =IF(O12=0,"Missing Price",IF(N12="Check","Wrong Quantity",IF(R12="Unknown","Missing Status",IF(J12="Unknown","Check Region","OK")))) -> OK | T12: 46113
A13: =TRIM(UPPER('Raw Data'!A13)) -> ORD012 | B13: =TRIM(UPPER('Raw Data'!B13)) -> C004 | C13: =TRIM(PROPER('Raw Data'!C13)) -> Rahul Das | D13: Kolkata | E13: West Bengal | F13: Premium | G13: =TRIM(UPPER('Raw Data'!D13)) -> P003 | H13: Laptop Pro | I13: Electronics | J13: =IF(TRIM(PROPER('Raw Data'!G13))="Nrth","North",TRIM(PROPER('Raw Data'!G13))) -> South | K13: 20-04-2026 | L13: 27-04-2026 | M13: 7 | N13: =IFERROR(VALUE('Raw Data'!J13),"Check") -> 1 | O13: =IFERROR(VALUE(SUBSTITUTE('Raw Data'!K13,"₹","")),0) -> 55000 | P13: =IFERROR('Raw Data'!L13*100,0) -> 12 | Q13: 48400 | R13: =IF(TRIM('Raw Data'!M13)="","Unknown",TRIM(PROPER('Raw Data'!M13))) -> Delivered | S13: =IF(O13=0,"Missing Price",IF(N13="Check","Wrong Quantity",IF(R13="Unknown","Missing Status",IF(J13="Unknown","Check Region","OK")))) -> OK | T13: 46113
A14: =TRIM(UPPER('Raw Data'!A14)) -> ORD013 | B14: =TRIM(UPPER('Raw Data'!B14)) -> C009 | C14: =TRIM(PROPER('Raw Data'!C14)) -> Arun Kumar | D14: Ahmedabad | E14: Gujarat | F14: Premium | G14: =TRIM(UPPER('Raw Data'!D14)) -> P002 | H14: Face Cream | I14: Beauty | J14: =IF(TRIM(PROPER('Raw Data'!G14))="Nrth","North",TRIM(PROPER('Raw Data'!G14))) -> East | K14: 28-04-2026 | L14: =IFERROR(DATEVALUE(TEXT('Raw Data'!I14,"DD-MM-YYYY")),"Invalid Date") -> 46146 | M14: 6 | N14: =IFERROR(VALUE('Raw Data'!J14),"Check") -> 3 | O14: =IFERROR(VALUE(SUBSTITUTE('Raw Data'!K14,"₹","")),0) -> 1200 | P14: =IFERROR('Raw Data'!L14*100,0) -> 5 | Q14: =IFERROR(N14*O14*(1-P14/100),0) -> 3420 | R14: =IF(TRIM('Raw Data'!M14)="","Unknown",TRIM(PROPER('Raw Data'!M14))) -> Pending | S14: =IF(O14=0,"Missing Price",IF(N14="Check","Wrong Quantity",IF(R14="Unknown","Missing Status",IF(J14="Unknown","Check Region","OK")))) -> OK | T14: 46113
A15: =TRIM(UPPER('Raw Data'!A15)) -> ORD014 | B15: =TRIM(UPPER('Raw Data'!B15)) -> C005 | C15: =TRIM(PROPER('Raw Data'!C15)) -> Divya Krishna | D15: Mumbai | E15: Maharashtra | F15: Regular | G15: =TRIM(UPPER('Raw Data'!D15)) -> P005 | H15: Rice Cooker | I15: Kitchen | J15: =IF(TRIM(PROPER('Raw Data'!G15))="Nrth","North",TRIM(PROPER('Raw Data'!G15))) -> West | K15: =IFERROR(DATEVALUE(TEXT('Raw Data'!H15,"DD-MM-YYYY")),"Invalid Date") -> 46147 | L15: 46361 | M15: 7 | N15: =IFERROR(VALUE('Raw Data'!J15),"Check") -> 1 | O15: =IFERROR(VALUE(SUBSTITUTE('Raw Data'!K15,"₹","")),0) -> 2800 | P15: =IFERROR('Raw Data'!L15*100,0) -> 0 | Q15: =IFERROR(N15*O15*(1-P15/100),0) -> 2800 | R15: =IF(TRIM('Raw Data'!M15)="","Unknown",TRIM(PROPER('Raw Data'!M15))) -> Delivered | S15: =IF(O15=0,"Missing Price",IF(N15="Check","Wrong Quantity",IF(R15="Unknown","Missing Status",IF(J15="Unknown","Check Region","OK")))) -> OK | T15: =TEXT(K15,"MMM-YYYY") -> May-2026
A16: =TRIM(UPPER('Raw Data'!A16)) -> ORD015 | B16: =TRIM(UPPER('Raw Data'!B16)) -> C010 | C16: =TRIM(PROPER('Raw Data'!C16)) -> Vijay Kumar | D16: Jaipur | E16: Rajasthan | F16: Regular | G16: =TRIM(UPPER('Raw Data'!D16)) -> P004 | H16: Running Shoes | I16: Sports | J16: =IF(TRIM(PROPER('Raw Data'!G16))="Nrth","North",TRIM(PROPER('Raw Data'!G16))) -> North | K16: =IFERROR(DATEVALUE(TEXT('Raw Data'!H16,"DD-MM-YYYY")),"Invalid Date") -> 46154 | L16: 19-05-2026 | M16: 7 | N16: =IFERROR(VALUE('Raw Data'!J16),"Check") -> 2 | O16: =IFERROR(VALUE(SUBSTITUTE('Raw Data'!K16,"₹","")),0) -> 3500 | P16: =IFERROR('Raw Data'!L16*100,0) -> 8 | Q16: =IFERROR(N16*O16*(1-P16/100),0) -> 6440 | R16: =IF(TRIM('Raw Data'!M16)="","Unknown",TRIM(PROPER('Raw Data'!M16))) -> Delivered | S16: =IF(O16=0,"Missing Price",IF(N16="Check","Wrong Quantity",IF(R16="Unknown","Missing Status",IF(J16="Unknown","Check Region","OK")))) -> OK | T16: =TEXT(K16,"MMM-YYYY") -> May-2026
A17: =TRIM(UPPER('Raw Data'!A17)) -> ORD016 | B17: =TRIM(UPPER('Raw Data'!B17)) -> C001 | C17: =TRIM(PROPER('Raw Data'!C17)) -> Priya Sharma | D17: Bangalore | E17: Karnataka | F17: Premium | G17: =TRIM(UPPER('Raw Data'!D17)) -> P001 | H17: Cotton Tshirt | I17: Fashion | J17: =IF(TRIM(PROPER('Raw Data'!G17))="Nrth","North",TRIM(PROPER('Raw Data'!G17))) -> North | K17: 18-05-2026 | L17: 24-05-2026 | M17: 6 | N17: =IFERROR(VALUE('Raw Data'!J17),"Check") -> 6 | O17: =IFERROR(VALUE(SUBSTITUTE('Raw Data'!K17,"₹","")),0) -> 799 | P17: =IFERROR('Raw Data'!L17*100,0) -> 10 | Q17: =IFERROR(N17*O17*(1-P17/100),0) -> 4314.6 | R17: =IF(TRIM('Raw Data'!M17)="","Unknown",TRIM(PROPER('Raw Data'!M17))) -> Delivered | S17: =IF(O17=0,"Missing Price",IF(N17="Check","Wrong Quantity",IF(R17="Unknown","Missing Status",IF(J17="Unknown","Check Region","OK")))) -> OK | T17: 46143
A18: =TRIM(UPPER('Raw Data'!A18)) -> ORD017 | B18: =TRIM(UPPER('Raw Data'!B18)) -> C006 | C18: =TRIM(PROPER('Raw Data'!C18)) -> Meera Nair | D18: Kochi | E18: Kerala | F18: Premium | G18: =TRIM(UPPER('Raw Data'!D18)) -> P003 | H18: Laptop Pro | I18: Electronics | J18: =IF(TRIM(PROPER('Raw Data'!G18))="Nrth","North",TRIM(PROPER('Raw Data'!G18))) -> East | K18: 25-05-2026 | L18: 31-05-2026 | M18: 6 | N18: =IFERROR(VALUE('Raw Data'!J18),"Check") -> 1 | O18: =IFERROR(VALUE(SUBSTITUTE('Raw Data'!K18,"₹","")),0) -> 55000 | P18: =IFERROR('Raw Data'!L18*100,0) -> 5 | Q18: =IFERROR(N18*O18*(1-P18/100),0) -> 52250 | R18: =IF(TRIM('Raw Data'!M18)="","Unknown",TRIM(PROPER('Raw Data'!M18))) -> Delivered | S18: =IF(O18=0,"Missing Price",IF(N18="Check","Wrong Quantity",IF(R18="Unknown","Missing Status",IF(J18="Unknown","Check Region","OK")))) -> OK | T18: 46143
A19: =TRIM(UPPER('Raw Data'!A19)) -> ORD018 | B19: =TRIM(UPPER('Raw Data'!B19)) -> C002 | C19: =TRIM(PROPER('Raw Data'!C19)) -> Arjun Nair | D19: Chennai | E19: Tamil Nadu | F19: Regular | G19: =TRIM(UPPER('Raw Data'!D19)) -> P002 | H19: Face Cream | I19: Beauty | J19: =IF(TRIM(PROPER('Raw Data'!G19))="Nrth","North",TRIM(PROPER('Raw Data'!G19))) -> South | K19: =IFERROR(DATEVALUE(TEXT('Raw Data'!H19,"DD-MM-YYYY")),"Invalid Date") -> 46174 | L19: =IFERROR(DATEVALUE(TEXT('Raw Data'!I19,"DD-MM-YYYY")),"Invalid Date") -> 46180 | M19: =IFERROR(L19-K19,"N/A") -> 6 | N19: =IFERROR(VALUE('Raw Data'!J19),"Check") -> 2 | O19: =IFERROR(VALUE(SUBSTITUTE('Raw Data'!K19,"₹","")),0) -> 1200 | P19: =IFERROR('Raw Data'!L19*100,0) -> 0 | Q19: =IFERROR(N19*O19*(1-P19/100),0) -> 2400 | R19: =IF(TRIM('Raw Data'!M19)="","Unknown",TRIM(PROPER('Raw Data'!M19))) -> Pending | S19: =IF(O19=0,"Missing Price",IF(N19="Check","Wrong Quantity",IF(R19="Unknown","Missing Status",IF(J19="Unknown","Check Region","OK")))) -> OK | T19: =TEXT(K19,"MMM-YYYY") -> Jun-2026
A20: =TRIM(UPPER('Raw Data'!A20)) -> ORD019 | B20: =TRIM(UPPER('Raw Data'!B20)) -> C007 | C20: =TRIM(PROPER('Raw Data'!C20)) -> Kiran Rao | D20: Pune | E20: Maharashtra | F20: Regular | G20: =TRIM(UPPER('Raw Data'!D20)) -> P004 | H20: Running Shoes | I20: Sports | J20: =IF(TRIM(PROPER('Raw Data'!G20))="Nrth","North",TRIM(PROPER('Raw Data'!G20))) -> West | K20: =IFERROR(DATEVALUE(TEXT('Raw Data'!H20,"DD-MM-YYYY")),"Invalid Date") -> 46178 | L20: =IFERROR(DATEVALUE(TEXT('Raw Data'!I20,"DD-MM-YYYY")),"Invalid Date") -> 46185 | M20: =IFERROR(L20-K20,"N/A") -> 7 | N20: =IFERROR(VALUE('Raw Data'!J20),"Check") -> 3 | O20: =IFERROR(VALUE(SUBSTITUTE('Raw Data'!K20,"₹","")),0) -> 3500 | P20: =IFERROR('Raw Data'!L20*100,0) -> 15 | Q20: =IFERROR(N20*O20*(1-P20/100),0) -> 8925 | R20: =IF(TRIM('Raw Data'!M20)="","Unknown",TRIM(PROPER('Raw Data'!M20))) -> Delivered | S20: =IF(O20=0,"Missing Price",IF(N20="Check","Wrong Quantity",IF(R20="Unknown","Missing Status",IF(J20="Unknown","Check Region","OK")))) -> OK | T20: =TEXT(K20,"MMM-YYYY") -> Jun-2026
A21: =TRIM(UPPER('Raw Data'!A21)) -> ORD020 | B21: =TRIM(UPPER('Raw Data'!B21)) -> C008 | C21: =TRIM(PROPER('Raw Data'!C21)) -> Pooja Singh | D21: Delhi | E21: Delhi | F21: Regular | G21: =TRIM(UPPER('Raw Data'!D21)) -> P005 | H21: Rice Cooker | I21: Kitchen | J21: =IF(TRIM(PROPER('Raw Data'!G21))="Nrth","North",TRIM(PROPER('Raw Data'!G21))) -> North | K21: =IFERROR(DATEVALUE(TEXT('Raw Data'!H21,"DD-MM-YYYY")),"Invalid Date") -> 46183 | L21: 17-06-2026 | M21: 7 | N21: =IFERROR(VALUE('Raw Data'!J21),"Check") -> 1 | O21: =IFERROR(VALUE(SUBSTITUTE('Raw Data'!K21,"₹","")),0) -> 2800 | P21: =IFERROR('Raw Data'!L21*100,0) -> 10 | Q21: =IFERROR(N21*O21*(1-P21/100),0) -> 2520 | R21: =IF(TRIM('Raw Data'!M21)="","Unknown",TRIM(PROPER('Raw Data'!M21))) -> Delivered | S21: =IF(O21=0,"Missing Price",IF(N21="Check","Wrong Quantity",IF(R21="Unknown","Missing Status",IF(J21="Unknown","Check Region","OK")))) -> OK | T21: =TEXT(K21,"MMM-YYYY") -> Jun-2026
A22: =TRIM(UPPER('Raw Data'!A22)) -> ORD021 | B22: =TRIM(UPPER('Raw Data'!B22)) -> C009 | C22: =TRIM(PROPER('Raw Data'!C22)) -> Arun Kumar | D22: Ahmedabad | E22: Gujarat | F22: Premium | G22: =TRIM(UPPER('Raw Data'!D22)) -> P001 | H22: Cotton Tshirt | I22: Fashion | J22: =IF(TRIM(PROPER('Raw Data'!G22))="Nrth","North",TRIM(PROPER('Raw Data'!G22))) -> East | K22: =IFERROR(DATEVALUE(TEXT('Raw Data'!H22,"DD-MM-YYYY")),"Invalid Date") -> 46185 | L22: 18-06-2026 | M22: 6 | N22: =IFERROR(VALUE('Raw Data'!J22),"Check") -> 2 | O22: =IFERROR(VALUE(SUBSTITUTE('Raw Data'!K22,"₹","")),0) -> 799 | P22: =IFERROR('Raw Data'!L22*100,0) -> 5 | Q22: =IFERROR(N22*O22*(1-P22/100),0) -> 1518.1 | R22: =IF(TRIM('Raw Data'!M22)="","Unknown",TRIM(PROPER('Raw Data'!M22))) -> Delivered | S22: =IF(O22=0,"Missing Price",IF(N22="Check","Wrong Quantity",IF(R22="Unknown","Missing Status",IF(J22="Unknown","Check Region","OK")))) -> OK | T22: =TEXT(K22,"MMM-YYYY") -> Jun-2026
A23: =TRIM(UPPER('Raw Data'!A23)) -> ORD022 | B23: =TRIM(UPPER('Raw Data'!B23)) -> C010 | C23: =TRIM(PROPER('Raw Data'!C23)) -> Vijay Kumar | D23: Jaipur | E23: Rajasthan | F23: Regular | G23: =TRIM(UPPER('Raw Data'!D23)) -> P003 | H23: Laptop Pro | I23: Electronics | J23: =IF(TRIM(PROPER('Raw Data'!G23))="Nrth","North",TRIM(PROPER('Raw Data'!G23))) -> South | K23: 14-06-2026 | L23: 21-06-2026 | M23: 7 | N23: =IFERROR(VALUE('Raw Data'!J23),"Check") -> 1 | O23: =IFERROR(VALUE(SUBSTITUTE('Raw Data'!K23,"₹","")),0) -> 55000 | P23: =IFERROR('Raw Data'!L23*100,0) -> 0 | Q23: =IFERROR(N23*O23*(1-P23/100),0) -> 55000 | R23: =IF(TRIM('Raw Data'!M23)="","Unknown",TRIM(PROPER('Raw Data'!M23))) -> Pending | S23: =IF(O23=0,"Missing Price",IF(N23="Check","Wrong Quantity",IF(R23="Unknown","Missing Status",IF(J23="Unknown","Check Region","OK")))) -> OK | T23: 46174
A24: =TRIM(UPPER('Raw Data'!A24)) -> ORD023 | B24: =TRIM(UPPER('Raw Data'!B24)) -> C003 | C24: =TRIM(PROPER('Raw Data'!C24)) -> Sneha Reddy | D24: Hyderabad | E24: Telangana | F24: Regular | G24: =TRIM(UPPER('Raw Data'!D24)) -> P002 | H24: Face Cream | I24: Beauty | J24: =IF(TRIM(PROPER('Raw Data'!G24))="Nrth","North",TRIM(PROPER('Raw Data'!G24))) -> North | K24: 16-06-2026 | L24: 22-06-2026 | M24: 6 | N24: =IFERROR(VALUE('Raw Data'!J24),"Check") -> 4 | O24: =IFERROR(VALUE(SUBSTITUTE('Raw Data'!K24,"₹","")),0) -> 1200 | P24: =IFERROR('Raw Data'!L24*100,0) -> 10 | Q24: =IFERROR(N24*O24*(1-P24/100),0) -> 4320 | R24: =IF(TRIM('Raw Data'!M24)="","Unknown",TRIM(PROPER('Raw Data'!M24))) -> Delivered | S24: =IF(O24=0,"Missing Price",IF(N24="Check","Wrong Quantity",IF(R24="Unknown","Missing Status",IF(J24="Unknown","Check Region","OK")))) -> OK | T24: 46174
A25: =TRIM(UPPER('Raw Data'!A25)) -> ORD024 | B25: =TRIM(UPPER('Raw Data'!B25)) -> C004 | C25: =TRIM(PROPER('Raw Data'!C25)) -> Rahul Das | D25: Kolkata | E25: West Bengal | F25: Premium | G25: =TRIM(UPPER('Raw Data'!D25)) -> P004 | H25: Running Shoes | I25: Sports | J25: =IF(TRIM(PROPER('Raw Data'!G25))="Nrth","North",TRIM(PROPER('Raw Data'!G25))) -> West | K25: 18-06-2026 | L25: 25-06-2026 | M25: 7 | N25: =IFERROR(VALUE('Raw Data'!J25),"Check") -> 2 | O25: =IFERROR(VALUE(SUBSTITUTE('Raw Data'!K25,"₹","")),0) -> 3500 | P25: =IFERROR('Raw Data'!L25*100,0) -> 5 | Q25: =IFERROR(N25*O25*(1-P25/100),0) -> 6650 | R25: =IF(TRIM('Raw Data'!M25)="","Unknown",TRIM(PROPER('Raw Data'!M25))) -> Delivered | S25: =IF(O25=0,"Missing Price",IF(N25="Check","Wrong Quantity",IF(R25="Unknown","Missing Status",IF(J25="Unknown","Check Region","OK")))) -> OK | T25: 46174
A26: =TRIM(UPPER('Raw Data'!A26)) -> ORD025 | B26: =TRIM(UPPER('Raw Data'!B26)) -> C005 | C26: =TRIM(PROPER('Raw Data'!C26)) -> Divya Krishna | D26: Mumbai | E26: Maharashtra | F26: Regular | G26: =TRIM(UPPER('Raw Data'!D26)) -> P005 | H26: Rice Cooker | I26: Kitchen | J26: =IF(TRIM(PROPER('Raw Data'!G26))="Nrth","North",TRIM(PROPER('Raw Data'!G26))) -> North | K26: 20-06-2026 | L26: 27-06-2026 | M26: 7 | N26: =IFERROR(VALUE('Raw Data'!J26),"Check") -> 3 | O26: =IFERROR(VALUE(SUBSTITUTE('Raw Data'!K26,"₹","")),0) -> 2800 | P26: =IFERROR('Raw Data'!L26*100,0) -> 8 | Q26: =IFERROR(N26*O26*(1-P26/100),0) -> 7728 | R26: =IF(TRIM('Raw Data'!M26)="","Unknown",TRIM(PROPER('Raw Data'!M26))) -> Delivered | S26: =IF(O26=0,"Missing Price",IF(N26="Check","Wrong Quantity",IF(R26="Unknown","Missing Status",IF(J26="Unknown","Check Region","OK")))) -> OK | T26: 46174
A27: =TRIM(UPPER('Raw Data'!A28)) -> ORD026 | B27: =TRIM(UPPER('Raw Data'!B28)) -> C006 | C27: =TRIM(PROPER('Raw Data'!C28)) -> Meera Nair | D27: Kochi | E27: Kerala | F27: Premium | G27: =TRIM(UPPER('Raw Data'!D28)) -> P001 | H27: Cotton Tshirt | I27: Fashion | J27: =IF(TRIM(PROPER('Raw Data'!G28))="Nrth","North",TRIM(PROPER('Raw Data'!G28))) -> North | K27: 21-06-2026 | L27: 28-06-2026 | M27: 7 | N27: =IFERROR(VALUE('Raw Data'!J28),"Check") -> 3 | O27: =IFERROR(VALUE(SUBSTITUTE('Raw Data'!K28,"₹","")),0) -> 799 | P27: =IFERROR('Raw Data'!L28*100,0) -> 5 | Q27: =IFERROR(N27*O27*(1-P27/100),0) -> 2277.15 | R27: =IF(TRIM('Raw Data'!M28)="","Unknown",TRIM(PROPER('Raw Data'!M28))) -> Delivered | S27: =IF(O27=0,"Missing Price",IF(N27="Check","Wrong Quantity",IF(R27="Unknown","Missing Status",IF(J27="Unknown","Check Region","OK")))) -> OK | T27: 46174
A28: =TRIM(UPPER('Raw Data'!A29)) -> ORD027 | B28: =TRIM(UPPER('Raw Data'!B29)) -> C007 | C28: =TRIM(PROPER('Raw Data'!C29)) -> Kiran Rao | D28: Pune | E28: Maharashtra | F28: Regular | G28: =TRIM(UPPER('Raw Data'!D29)) -> P003 | H28: Laptop Pro | I28: Electronics | J28: =IF(TRIM(PROPER('Raw Data'!G29))="Nrth","North",TRIM(PROPER('Raw Data'!G29))) -> West | K28: 22-06-2026 | L28: 29-06-2026 | M28: 7 | N28: =IFERROR(VALUE('Raw Data'!J29),"Check") -> 1 | O28: =IFERROR(VALUE(SUBSTITUTE('Raw Data'!K29,"₹","")),0) -> 0 | P28: =IFERROR('Raw Data'!L29*100,0) -> 10 | Q28: =IFERROR(N28*O28*(1-P28/100),0) -> 0 | R28: =IF(TRIM('Raw Data'!M29)="","Unknown",TRIM(PROPER('Raw Data'!M29))) -> Pending | S28: =IF(O28=0,"Missing Price",IF(N28="Check","Wrong Quantity",IF(R28="Unknown","Missing Status",IF(J28="Unknown","Check Region","OK")))) -> Missing Price | T28: 46174
A29: =TRIM(UPPER('Raw Data'!A30)) -> ORD028 | B29: =TRIM(UPPER('Raw Data'!B30)) -> C008 | C29: =TRIM(PROPER('Raw Data'!C30)) -> Pooja Singh | D29: Delhi | E29: Delhi | F29: Regular | G29: =TRIM(UPPER('Raw Data'!D30)) -> P004 | H29: Running Shoes | I29: Sports | J29: =IF(TRIM(PROPER('Raw Data'!G30))="Nrth","North",TRIM(PROPER('Raw Data'!G30))) -> South | K29: 23-06-2026 | L29: 30-06-2026 | M29: 7 | N29: =IFERROR(VALUE('Raw Data'!J30),"Check") -> 2 | O29: =IFERROR(VALUE(SUBSTITUTE('Raw Data'!K30,"₹","")),0) -> 3500 | P29: =IFERROR('Raw Data'!L30*100,0) -> 0 | Q29: =IFERROR(N29*O29*(1-P29/100),0) -> 7000 | R29: =IF(TRIM('Raw Data'!M30)="","Unknown",TRIM(PROPER('Raw Data'!M30))) -> Unknown | S29: =IF(O29=0,"Missing Price",IF(N29="Check","Wrong Quantity",IF(R29="Unknown","Missing Status",IF(J29="Unknown","Check Region","OK")))) -> Missing Status | T29: 46174
A30: =TRIM(UPPER('Raw Data'!A31)) -> ORD029 | B30: =TRIM(UPPER('Raw Data'!B31)) -> C009 | C30: =TRIM(PROPER('Raw Data'!C31)) -> Arun Kumar | D30: Ahmedabad | E30: Gujarat | F30: Premium | G30: =TRIM(UPPER('Raw Data'!D31)) -> P005 | H30: Rice Cooker | I30: Kitchen | J30: =IF(TRIM(PROPER('Raw Data'!G31))="Nrth","North",TRIM(PROPER('Raw Data'!G31))) -> East | K30: 24-06-2026 | L30: =IFERROR(DATEVALUE(TEXT('Raw Data'!I31,"DD-MM-YYYY")),"Invalid Date") -> 46204 | M30: 7 | N30: =IFERROR(VALUE('Raw Data'!J31),"Check") -> 2 | O30: =IFERROR(VALUE(SUBSTITUTE('Raw Data'!K31,"₹","")),0) -> 2800 | P30: =IFERROR('Raw Data'!L31*100,0) -> 5 | Q30: =IFERROR(N30*O30*(1-P30/100),0) -> 5320 | R30: =IF(TRIM('Raw Data'!M31)="","Unknown",TRIM(PROPER('Raw Data'!M31))) -> Delivered | S30: =IF(O30=0,"Missing Price",IF(N30="Check","Wrong Quantity",IF(R30="Unknown","Missing Status",IF(J30="Unknown","Check Region","OK")))) -> OK | T30: 46174

Sheet Analysis
A1: E-COMMERCE SALES ANALYSIS | F1: KPI SUMMARY | H1: Status | I1: Count
F2: Total Revenue | G2: =SUM(Cleaned!Q2:Q28) -> 391696.25 | H2: Delivered | I2: =COUNTIF(Cleaned!R2:R30,"Delivered") -> 21
A3: 1. Revenue by Region | F3: Total Orders | G3: =COUNTA(Cleaned!A2:A28) -> 27 | H3: Pending | I3: =COUNTIF(Cleaned!R2:R30,"Pending") -> 6
A4: Region | B4: Total Revenue | C4: Order Count | D4: % of Total | F4: Avg Order Value | G4: =IFERROR(G2/G3,0) -> 14507.269 | H4: Cancelled | I4: =COUNTIF(Cleaned!R2:R30,"Cancelled") -> 1
A5: North | B5: =IFERROR(SUMIF(Cleaned!$J$2:$J$28,A5,Cleaned!$Q$2:$Q$28),0) -> 135170.75 | C5: =IFERROR(COUNTIF(Cleaned!$J$2:$J$28,A5),0) -> 10 | D5: =IFERROR(B5/$B$9*100,0) -> 34.509074 | F5: Highest Single Order | G5: =MAX(Cleaned!Q2:Q28) -> 99000
A6: South | B6: =IFERROR(SUMIF(Cleaned!$J$2:$J$28,A6,Cleaned!$Q$2:$Q$28),0) -> 162472.4 | C6: =IFERROR(COUNTIF(Cleaned!$J$2:$J$28,A6),0) -> 6 | D6: =IFERROR(B6/$B$9*100,0) -> 41.479182 | F6: Lowest Single Order | G6: =IFERROR(_xlfn.MINIFS(Cleaned!Q2:Q28,Cleaned!Q2:Q28,">"&0),0) -> 1200
A7: East | B7: =IFERROR(SUMIF(Cleaned!$J$2:$J$28,A7,Cleaned!$Q$2:$Q$28),0) -> 70358.1 | C7: =IFERROR(COUNTIF(Cleaned!$J$2:$J$28,A7),0) -> 6 | D7: =IFERROR(B7/$B$9*100,0) -> 17.962413 | F7: Delivered Orders | G7: =COUNTIF(Cleaned!R2:R28,"Delivered") -> 20
A8: West | B8: =IFERROR(SUMIF(Cleaned!$J$2:$J$28,A8,Cleaned!$Q$2:$Q$28),0) -> 23695 | C8: =IFERROR(COUNTIF(Cleaned!$J$2:$J$28,A8),0) -> 5 | D8: =IFERROR(B8/$B$9*100,0) -> 6.0493303 | F8: Pending Orders | G8: =COUNTIF(Cleaned!R2:R28,"Pending") -> 6
A9: TOTAL | B9: =SUM(B5:B8) -> 391696.25 | C9: =SUM(C5:C8) -> 27 | F9: Cancelled Orders | G9: =COUNTIF(Cleaned!R2:R30,"Cancelled") -> 1
F10: Delivery Rate % | G10: =IFERROR(G7/G3*100,0) -> 74.074074
A11: 2. Orders & Revenue by Category
A12: Category | B12: Total Revenue | C12: Order Count
A13: Electronics | B13: =IFERROR(SUMIF(Cleaned!$I$2:$I$28,A13,Cleaned!$Q$2:$Q$28),0) -> 305250 | C13: =IFERROR(COUNTIF(Cleaned!$I$2:$I$28,A13),0) -> 6
A14: Fashion | B14: =IFERROR(SUMIF(Cleaned!$I$2:$I$28,A14,Cleaned!$Q$2:$Q$28),0) -> 17378.25 | C14: =IFERROR(COUNTIF(Cleaned!$I$2:$I$28,A14),0) -> 6
A15: Beauty | B15: =IFERROR(SUMIF(Cleaned!$I$2:$I$28,A15,Cleaned!$Q$2:$Q$28),0) -> 13740 | C15: =IFERROR(COUNTIF(Cleaned!$I$2:$I$28,A15),0) -> 5
A16: Sports | B16: =IFERROR(SUMIF(Cleaned!$I$2:$I$28,A16,Cleaned!$Q$2:$Q$28),0) -> 34440 | C16: =IFERROR(COUNTIF(Cleaned!$I$2:$I$28,A16),0) -> 5
A17: Kitchen | B17: =IFERROR(SUMIF(Cleaned!$I$2:$I$28,A17,Cleaned!$Q$2:$Q$28),0) -> 20888 | C17: =IFERROR(COUNTIF(Cleaned!$I$2:$I$28,A17),0) -> 5
A18: TOTAL | B18: =SUM(B13:B17) -> 391696.25 | C18: =SUM(C13:C17) -> 27
A20: 3. Revenue by Month
A21: Month | B21: Total Revenue | C21: Order Count
A22: =Cleaned!T2 -> Jan-2026 | B22: =IFERROR(SUMIF(Cleaned!$T$2:$T$28,A22,Cleaned!$Q$2:$Q$28),0) -> 101277.15 | C22: =IFERROR(COUNTIF(Cleaned!$T$2:$T$28,A22),0) -> 2
A23: =Cleaned!T4 -> Feb-2026 | B23: =IFERROR(SUMIF(Cleaned!$T$2:$T$28,A23,Cleaned!$Q$2:$Q$28),0) -> 7970.25 | C23: =IFERROR(COUNTIF(Cleaned!$T$2:$T$28,A23),0) -> 3
A24: =Cleaned!T7 -> Mar-2026 | B24: =IFERROR(SUMIF(Cleaned!$T$2:$T$28,A24,Cleaned!$Q$2:$Q$28),0) -> 55520 | C24: =IFERROR(COUNTIF(Cleaned!$T$2:$T$28,A24),0) -> 3
A25: =Cleaned!T10 -> Apr-2026 | B25: =IFERROR(SUMIF(Cleaned!$T$2:$T$28,A25,Cleaned!$Q$2:$Q$28),0) -> 69786 | C25: =IFERROR(COUNTIF(Cleaned!$T$2:$T$28,A25),0) -> 5
A26: =Cleaned!T15 -> May-2026 | B26: =IFERROR(SUMIF(Cleaned!$T$2:$T$28,A26,Cleaned!$Q$2:$Q$28),0) -> 65804.6 | C26: =IFERROR(COUNTIF(Cleaned!$T$2:$T$28,A26),0) -> 4
A27: =Cleaned!T19 -> Jun-2026 | B27: =IFERROR(SUMIF(Cleaned!$T$2:$T$28,A27,Cleaned!$Q$2:$Q$28),0) -> 91338.25 | C27: =IFERROR(COUNTIF(Cleaned!$T$2:$T$28,A27),0) -> 10
A28: TOTAL | B28: =SUM(B22:B27) -> 391696.25 | C28: =SUM(C22:C27) -> 27
A29: 4. Top 5 Orders by Revenue
A30: Rank | B30: Order ID | C30: Customer Name | D30: Revenue
A31: 1 | B31: =IFERROR(INDEX(Cleaned!$A$2:$A$28,MATCH(D31,Cleaned!$Q$2:$Q$28,0)),"") -> ORD001 | C31: =IFERROR(INDEX(Cleaned!$C$2:$C$28,MATCH(D31,Cleaned!$Q$2:$Q$28,0)),"") -> Priya Sharma | D31: =IFERROR(LARGE(Cleaned!$Q$2:$Q$28,A31),0) -> 99000
A32: 2 | B32: =IFERROR(INDEX(Cleaned!$A$2:$A$28,MATCH(D32,Cleaned!$Q$2:$Q$28,0)),"") -> ORD022 | C32: =IFERROR(INDEX(Cleaned!$C$2:$C$28,MATCH(D32,Cleaned!$Q$2:$Q$28,0)),"") -> Vijay Kumar | D32: =IFERROR(LARGE(Cleaned!$Q$2:$Q$28,A32),0) -> 55000
A33: 3 | B33: =IFERROR(INDEX(Cleaned!$A$2:$A$28,MATCH(D33,Cleaned!$Q$2:$Q$28,0)),"") -> ORD017 | C33: =IFERROR(INDEX(Cleaned!$C$2:$C$28,MATCH(D33,Cleaned!$Q$2:$Q$28,0)),"") -> Meera Nair | D33: =IFERROR(LARGE(Cleaned!$Q$2:$Q$28,A33),0) -> 52250
A34: 4 | B34: =IFERROR(INDEX(Cleaned!$A$2:$A$28,MATCH(D34,Cleaned!$Q$2:$Q$28,0)),"") -> ORD007 | C34: =IFERROR(INDEX(Cleaned!$C$2:$C$28,MATCH(D34,Cleaned!$Q$2:$Q$28,0)),"") -> Arjun Nair | D34: =IFERROR(LARGE(Cleaned!$Q$2:$Q$28,A34),0) -> 50600
A35: 5 | B35: =IFERROR(INDEX(Cleaned!$A$2:$A$28,MATCH(D35,Cleaned!$Q$2:$Q$28,0)),"") -> ORD012 | C35: =IFERROR(INDEX(Cleaned!$C$2:$C$28,MATCH(D35,Cleaned!$Q$2:$Q$28,0)),"") -> Rahul Das | D35: =IFERROR(LARGE(Cleaned!$Q$2:$Q$28,A35),0) -> 48400
A37: 5. Customer Analysis
A38: Customer Name | B38: City | C38: Total Revenue | D38: Order Count | E38: Rank
A39: Priya Sharma | B39: Bangalore | C39: =IFERROR(SUMIF(Cleaned!$C$2:$C$28,A39,Cleaned!$Q$2:$Q$28),0) -> 106289.6 | D39: =IFERROR(COUNTIF(Cleaned!$C$2:$C$28,A39),0) -> 3 | E39: =RANK(C39,$C$39:$C$44,0) -> 1
A40: Arjun Nair | B40: =IFERROR(VLOOKUP(A40,CustomerDB!B2:D12,2,0),"Unknown") -> Chennai | C40: =IFERROR(SUMIF(Cleaned!$C$2:$C$28,A40,Cleaned!$Q$2:$Q$28),0) -> 55277.15 | D40: =IFERROR(COUNTIF(Cleaned!$C$2:$C$28,A40),0) -> 3 | E40: =RANK(C40,$C$39:$C$44,0) -> 4
A41: Sneha Reddy | B41: =IFERROR(VLOOKUP(A41,CustomerDB!B3:D13,2,0),"Unknown") -> Hyderabad | C41: =IFERROR(SUMIF(Cleaned!$C$2:$C$28,A41,Cleaned!$Q$2:$Q$28),0) -> 14970 | D41: =IFERROR(COUNTIF(Cleaned!$C$2:$C$28,A41),0) -> 3 | E41: =RANK(C41,$C$39:$C$44,0) -> 5
A42: Rahul Das | B42: =IFERROR(VLOOKUP(A42,CustomerDB!B4:D14,2,0),"Unknown") -> Kolkata | C42: =IFERROR(SUMIF(Cleaned!$C$2:$C$28,A42,Cleaned!$Q$2:$Q$28),0) -> 58845.25 | D42: =IFERROR(COUNTIF(Cleaned!$C$2:$C$28,A42),0) -> 3 | E42: =RANK(C42,$C$39:$C$44,0) -> 2
...

Sheet Pivots
A1: Sum of Revenue | B1: Category
A2: Region | B2: Beauty | C2: Electronics | D2: Fashion | E2: Kitchen | F2: Sports | G2: Grand Total
A3: East | B3: 4620 | C3: 52250 | D3: 1518.1 | E3: 7840 | F3: 9450 | G3: 75678.1
A4: North | B4: 6720 | C4: 99000 | D4: 9787.75 | E4: 10248 | F4: 9415 | G4: 135170.75
A5: South | B5: 2400 | C5: 154000 | D5: 6072.4 | F5: 7000 | G5: 169472.4
A6: West | C6: 0 | E6: 8120 | F6: 15575 | G6: 23695
A7: Grand Total | B7: 13740 | C7: 305250 | D7: 17378.25 | E7: 26208 | F7: 41440 | G7: 404016.25
A10: Status | B10: (All)
A12: Month | B12: Sum of Revenue
A13: Apr-2026 | B13: 14770
A14: Feb-2026 | B14: 1200
A15: Jan-2026 | B15: 101277.15
A16: Jun-2026 | B16: 15363.1
A17: Mar-2026 | B17: 2520
A18: May-2026 | B18: 9240
A19: 46054 | B19: 6770.25
A20: 46082 | B20: 53000
A21: 46113 | B21: 55016
A22: 46143 | B22: 56564.6
A23: 46174 | B23: 88295.15
A24: Grand Total | B24: 404016.25
A27: Count of Order ID | B27: Status
A28: Customer Name | B28: Cancelled | C28: Delivered | D28: Pending | E28: Unknown | F28: Grand Total
A29: Arjun Nair | D29: 3 | F29: 3
A30: Arun Kumar | C30: 2 | D30: 1 | F30: 3
A31: Divya Krishna | C31: 3 | F31: 3
A32: Kiran Rao | C32: 2 | D32: 1 | F32: 3
A33: Meera Nair | C33: 3 | F33: 3
A34: Pooja Singh | C34: 2 | E34: 1 | F34: 3
A35: Priya Sharma | C35: 3 | F35: 3
A36: Rahul Das | B36: 1 | C36: 2 | F36: 3
A37: Sneha Reddy | C37: 3 | F37: 3
A38: Vijay Kumar | C38: 1 | D38: 1 | F38: 2
A39: Grand Total | B39: 1 | C39: 21 | D39: 6 | E39: 1 | F39: 29

Sheet Dashboard
B1: 🛒 E-Commerce Sales Performance Dashboard — 2026
A2: Data Period: Jan 2026 – Jun 2026 | Total Orders: 27 | Last Updated: Jun 2026
A4: TOTAL REVENUE | B4: TOTAL ORDERS | C4: AVG ORDER VALUE | D4: DELIVERY RATE
A5: =Analysis!G2 -> 391696.25 | B5: 27 | C5: =Analysis!G4 -> 14507.269 | D5: =ROUND(Analysis!G10,1)&"%" -> 74.1%
A6: All Regions Combined | B6: Jan – Jun 2026 | C6: Per Transaction | D6: Orders Delivered Successfully
C23: Data Source: Simulated E-Commerce Sales Data 2026
C24: Raw Records: 30 orders (1 duplicate removed)
C25: Clean Records: 29 orders across 4 regions
C26: Products: 5 categories
C27: Customers: 10 unique customers
C28: Built with: Excel Online + Power BI Desktop | D28: Created by: [Swathi M]
